Workbook

Sheet Summary
A1: Percentage | B1: Centimorgans
A2: 0.34 | B2: =A2*74.67 -> 25.3878
A3: Centimorgans | B3: Percentage
A4: 187 | B4: =A4/74.67 -> 2.5043525
A6: Worksheet Name | B6: DNA Matches | C6: RANK | D6: PARENT | E6: GRANDPARENTS | F6: 1G GRANDPARENTS | G6: 2G GRANDPARENTS | H6: 3G GRANDPARENTS | I6: 4G GRANDPARENTS | J6: 5G GRANDPARENTS | K6: 6G GRANDPARENTS | L6: 7G GRANDPARENTS
B7: =SUM(Angier:Wilson!B1) -> 616
A8: Alderman | B8: =Alderman!B1 -> 1 | C8: =RANK(B8,$B$9:$B$60) -> 43 | D8: ROBERTSON | E8: ROBERTSON | F8: PATRICK | G8: PATRICK | H8: PATRICK | I8: PATRICK | J8: MILLER | K8: ALDERMAN
A9: Angier | B9: =Angier!B1 -> 3 | C9: =RANK(B9,$B$9:$B$60) -> 37 | D9: HALL | E9: HALL | F9: SHICKLE | G9: DISDALE | H9: DISDALE | I9: ANGIER
A10: Argent | B10: =Argent!B1 -> 3 | C10: =RANK(B10,$B$9:$B$60) -> 37 | D10: ROBERTSON | E10: WILSON | F10: BEAVIS | G10: BEAVIS | H10: BEAVIS | I10: BEAVIS | J10: ARGENT
A11: Beavis | B11: =Beavis!B1 -> 33 | C11: =RANK(B11,$B$9:$B$60) -> 6 | D11: ROBERTSON | E11: WILSON | F11: BEAVIS
A12: Biddle | B12: =Biddle!B1 -> 35 | C12: =RANK(B12,$B$9:$B$60) -> 4 | D12: ROBERTSON | E12: ROBERTSON | F12: ROBERTSON | G12: PATRICK | H12: BIDDLE
A13: Bing | B13: =Bing!B1 -> 1 | C13: =RANK(B13,$B$9:$B$60) -> 43 | D13: HALL | E13: TUCKER | F13: JEZZARD | G13: BUSHELL | H13: MERCER | I13: MERCER | J13: BING
A14: Bloomfield | B14: =Bloomfield!B1 -> 22 | C14: =RANK(B14,$B$9:$B$60) -> 10 | D14: HALL | E14: BRINKLEY | F14: BRINKLEY | G14: OTLEY | H14: OTLEY | I14: BLOOMFIELD
A15: Boreham | B15: =Boreham!B1 -> 16 | C15: =RANK(B15,$B$9:$B$60) -> 14 | D15: ROBERTSON | E15: WILSON | F15: WILSON | G15: BOREHAM
A16: Brinkley | B16: =Brinkley!B1 -> 43 | C16: =RANK(B16,$B$9:$B$60) -> 2 | D16: HALL | E16: HALL | F16: BRINKLEY
A17: Bushell | B17: =Bushell!B1 -> 28 | C17: =RANK(B17,$B$9:$B$60) -> 7 | D17: HALL | E17: TUCKER | F17: JEZZARD | G17: BUSHELL
A18: Camp | B18: =Camp!B1 -> 2 | C18: =RANK(B18,$B$9:$B$60) -> 40 | D18: ROBERTSON | E18: WILSON | F18: BEAVIS | G18: BOREHAM | H18: BOREHAM | I18: CAMP
A19: Collins | B19: =Collins!B1 -> 11 | C19: =RANK(B19,$B$9:$B$60) -> 22 | D19: HALL | E19: TUCKER | F19: TUCKER | G19: FREEMANTLE | H19: COLLINS
A20: Dadley | B20: =Dadley!B1 -> 1 | C20: =RANK(B20,$B$9:$B$60) -> 43 | D20: ROBERTSON | E20: ROBERTSON | F20: ROBERTSON | G20: PATRICK | H20: BIDDLE | I20: BIDDLE | J20: DADLEY
A21: Davis | B21: =Davis!B1 -> 1 | C21: =RANK(B21,$B$9:$B$60) -> 43 | D21: HALL | E21: TUCKER | F21: JEZZARD | G21: JEZZARD | H21: JEZZARD | I21: DAVIS
A22: Dibel | B22: =Dibel!B1 -> 1 | C22: =RANK(B22,$B$9:$B$60) -> 43 | D22: HALL | E22: TUCKER | F22: JEZZARD | G22: BUSHELL | H22: MERCER | I22: MAY | J22: MAYES | K22: DIBAL
A23: Disdale | B23: =Disdale!B1 -> 4 | C23: =RANK(B23,$B$9:$B$60) -> 30 | D23: HALL | E23: HALL | F23: BRINKLEY | G23: SHICKLE | H23: DISDALE
A24: Dyason | B24: =Dyason!B1 -> 12 | C24: =RANK(B24,$B$9:$B$60) -> 20 | D24: HALL | E24: TUCKER | F24: JEZZARD | G24: BUSHELL | H24: MERCER | I24: MERCER | J24: BING | K24: DYASON
A25: Felton | B25: =Felton!B1 -> 2 | C25: =RANK(B25,$B$9:$B$60) -> 40 | D25: ROBERTSON | E25: WILSON | F25: WILSON | G25: BOREHAM | H25: RAYNER | I25: FELTON
A26: Field | B26: =Field!B1 -> 1 | C26: =RANK(B26,$B$9:$B$60) -> 43 | D26: ROBERTSON | E26: WILSON | F26: WILSON | G26: WILSON | H26: SAMS | I26: SAMS | J26: STYLEMAN | K26: STYLEMAN | L26: FIELD
A27: Fooks | B27: =Fooks!B1 -> 7 | C27: =RANK(B27,$B$9:$B$60) -> 26 | D27: HALL | E27: TUCKER | F27: TUCKER | G27: TUCKER | H27: FOOKS
A28: Ford | B28: =Ford!B1 -> 10 | C28: =RANK(B28,$B$9:$B$60) -> 24 | D28: HALL | E28: HALL | F28: HALL | G28: FORD
A29: Freemantle | B29: =Freemantle!B1 -> 14 | C29: =RANK(B29,$B$9:$B$60) -> 18 | D29: HALL | E29: TUCKER | F29: TUCKER | G29: FREEMANTLE
A30: Gates | B30: =Gates!B1 -> 1 | C30: =RANK(B30,$B$9:$B$60) -> 43 | D30: HALL | E30: HALL | F30: BRINKLEY | G30: BRINKLEY | H30: OTLEY | I30: GATES
A31: Hall | B31: =Hall!B1 -> 36 | C31: =RANK(B31,$B$9:$B$60) -> 3 | D31: HALL
A32: Hook | B32: =Hook!B1 -> 1 | C32: =RANK(B32,$B$9:$B$60) -> 43 | D32: HALL | E32: TUCKER | F32: TUCKER | G32: TUCKER | H32: TUCKER | I32: HOOK
A33: Hogben | B33: =Hogben!B1 -> 6 | C33: =RANK(B33,$B$9:$B$60) -> 28 | D33: HALL | E33: TUCKER | F33: JEZZARD | G33: BUSHELL | H33: BUSHELL | I33: BUSHELL | J33: HOGBEN
A34: Hughes | B34: =Hughes!B1 -> 3 | C34: =RANK(B34,$B$9:$B$60) -> 37 | D34: HALL | E34: HALL | F34: PENNY | G34: HUGHES
A35: Humphrey | B35: =Humphrey!B1 -> 4 | C35: =RANK(B35,$B$9:$B$60) -> 30 | D35: ROBERTSON | E35: WILSON | F35: BEAVIS | G35: BEAVIS | H35: BEAVIS | I35: HUMPHREY
A36: Jezzard | B36: =Jezzard!B1 -> 35 | C36: =RANK(B36,$B$9:$B$60) -> 4 | D36: HALL | E36: TUCKER | F36: JEZZARD
A37: Jordan | B37: =Jordan!B1 -> 4 | C37: =RANK(B37,$B$9:$B$60) -> 30 | D37: HALL | E37: TUCKER | F37: JEZZARD | G37: BUSHELL | H37: BUSHELL | I37: PITTOCK | J37: JORDAN
A38: Lippincott | B38: =Lippincott!B1 -> 24 | C38: =RANK(B38,$B$9:$B$60) -> 9 | D38: ROBERTSON | E38: ROBERTSON | F38: PATRICK | G38: BIDDLE | H38: BIDDLE | I38: BIDDLE | J38: SHINN | K38: LIPPINCOTT
A39: Mayes | B39: =Mayes!B1 -> 4 | C39: =RANK(B39,$B$9:$B$60) -> 30 | D39: HALL | E39: TUCKER | F39: JEZZARD | G39: BUSHELL | H39: MERCER | I39: MAY
A40: Mercer | B40: =Mercer!B1 -> 16 | C40: =RANK(B40,$B$9:$B$60) -> 14 | D40: HALL | E40: TUCKER | F40: JEZZARD | G40: BUSHELL | H40: MERCER
A41: Minter | B41: =Minter!B1 -> 2 | C41: =RANK(B41,$B$9:$B$60) -> 40 | D41: HALL | E41: TUCKER | F41: JEZZARD | G41: BUSHELL | H41: BUSHELL | I41: BUSHELL | J41: BUSHELL | K41: MINTER
...

Sheet Alderman
A1: Summary | B1: =COUNTIF(I2:I1072,C1)+COUNTIF(I2:I1072,D1) -> 1 | C1: Simon Leigh Robertson | D1: Jill Elaine Robertson
A2: Name | B2: Source | C2: Predicted Relationship | D2: Actual Relationship | E2: Shared DNA | F2: Common Male Ancestor | G2: Common Female Ancestor | H2: Relationship to Ancestor | I2: My Ancestry | J2: Matched Ancestry
A3: Mark Alderman | B3: Ancestry | C3: 5th-8th Cousin | D3: 8th Cousin 1xremoved | E3: 11cM | F3: John Alderman | G3: Dorothy Sargent | H3: 8G Grandparents | I3: Benjamin Alderman | J3: John Alderman
E4: 18cM | I4: Sarah Alderman | J4: John Alderman
I5: Mary Miller | J5: John Alderman
I6: Joseph Patrick | J6: William Alderman
I7: Thomas Patrick | J7: John Alderman
I8: William Simeon Patrick | J8: Charles William Alderman
I9: Emily Elizabeth Patrick | J9: Ernest Saunders Alderman
I10: Walter William Robertson | J10: Kenneth Walter Alderman
I11: Gordon Walter Robertson | J11: Mark K Alderman
I12: Simon Leigh Robertson

Sheet Angier
A1: Summary | B1: =COUNTIF(I2:I1080,C1)+COUNTIF(I2:I1080,D1) -> 3 | C1: Simon Leigh Robertson | D1: Jill Elaine Robertson
A2: Name | B2: Source | C2: Predicted Relationship | D2: Actual Relationship | E2: Shared DNA | F2: Common Male Ancestor | G2: Common Female Ancestor | H2: Relationship to Ancestor | I2: My Ancestry | J2: Matched Ancestry
A3: Douglas Eric Trent | B3: Ancestry | C3: 5th-8th Cousin | D3: 7th Cousin 1xremoved | E3: 10cM | F3: Cornelius Angier | G3: Martha Etheridge | H3: 6G Grandparents | I3: Margaret Angier | J3: Cornelius Angier
I4: John Disdale | J4: Charles Angier
I5: Emma Disdale | J5: Sarah Angier
I6: Susannah Shickle | J6: Robert Tweed
I7: Charlotte Lydia Brinkley | J7: Hannah Tweed
I8: Maud Bessie Hall | J8: Emma Hannah Opie
I9: June Margery Hall | J9: Charles Obert Trent
I10: Simon Leigh Robertson | J10: Douglas Eric Trent
A11: Desiree Bean | B11: Ancestry | C11: 5th-8th Cousin | D11: 7th Cousin 1xremoved | E11: 10cM | F11: Cornelius Angier | G11: Martha Etheridge | H11: 6G Grandparents | I11: Margaret Angier | J11: Cornelius Angier
I12: John Disdale | J12: Charles Angier
I13: Emma Disdale | J13: Sarah Angier
I14: Susannah Shickle | J14: Robert Tweed
I15: Charlotte Lydia Brinkley | J15: Hannah Tweed
I16: Maud Bessie Hall | J16: Emma Hannah Opie
I17: June Margery Hall | J17: Charles Obert Trent
I18: Simon Leigh Robertson | J18: Douglas Eric Trent
J19: Desiree Trent
A20: Edna Law | B20: Ancestry | C20: 5th-8th Cousin | D20: 6th Cousin 1xremoved | E20: 10cM | F20: Cornelius Angier | G20: Martha Etheridge | H20: 6G Grandparents | I20: Margaret Angier | J20: Robert Angier
I21: John Disdale | J21: Margaret Angier
I22: Emma Disdale | J22: Mary Deeks
I23: Susannah Shickle | J23: Thomas Rowland
I24: Charlotte Lydia Brinkley | J24: Walter F Rowland
I25: Maud Bessie Hall | J25: Rose Rowland
I26: June Margery Hall | J26: Edna Law
I27: Simon Leigh Robertson

Sheet Argent
A1: Summary | B1: =COUNTIF(I2:I1079,C1)+COUNTIF(I2:I1079,D1) -> 3 | C1: Simon Leigh Robertson | D1: Jill Elaine Robertson
A2: Name | B2: Source | C2: Predicted Relationship | D2: Actual Relationship | E2: Shared DNA | F2: Common Male Ancestor | G2: Common Female Ancestor | H2: Relationship to Ancestor | I2: My Ancestry | J2: Matched Ancestry
A3: Malcolm Haycox | B3: Ancestry | C3: 5th-8th Cousin | D3: 7th Cousin 1xremoved | E3: 14cM | F3: John Argent | G3: Elisabeth Goode | H3: 5G Grandparents | I3: Susannah Argent | J3: Susan Argent
I4: Thomas Beavis | J4: John Digsby
I5: James Beavis | J5: Eliza Digsby
I6: James Beavis | J6: John Cowell
I7: Mary Anne Beavis | J7: John Cowell
I8: Elsie Wilson | J8: Ellen Cowell
I9: Gordon Walter Robertson | J9: Elsie Elliston
I10: Simon Leigh Robertson | J10: Malcolm S Haycox
A11: Ann Flatman | B11: Ancestry | C11: 5th-8th Cousin | D11: 6th Cousin 1xremoved | E11: 10cM | F11: John Argent | G11: Elisabeth Goode | H11: 5G Grandparents | I11: Susannah Argent | J11: George Argent
I12: Thomas Beavis | J12: Susan Key Argent
I13: James Beavis | J13: Zachariah Goody
I14: James Beavis | J14: Jesse Goody
I15: Mary Anne Beavis | J15: Bertha Maria Goody
I16: Elsie Wilson | J16: Gus Flatman
I17: Gordon Walter Robertson | J17: Charles Flatman
I18: Simon Leigh Robertson | J18: Ann J Flatman
A19: peter_watson717 | B19: Ancestry | C19: 5th-8th Cousin | D19: 6th Cousin | E19: 6cM | F19: John Argent | G19: Sarah Brewster | H19: 5G Grandparents | I19: Susannah Argent | J19: John Argent
I20: Thomas Beavis | J20: John Argent
I21: James Beavis | J21: Joseph Argent
I22: James Beavis | J22: Laura Argent
I23: Mary Anne Beavis | J23: James Drew
I24: Elsie Wilson | J24: Kate drew
I25: Gordon Walter Robertson | J25: Peter A S Watson
I26: Simon Leigh Robertson

Sheet Beavis
A1: Summary | B1: =COUNTIF(I2:I1218,C1)+COUNTIF(I2:I1218,D1) -> 33 | C1: Simon Leigh Robertson | D1: Jill Elaine Robertson
A2: Name | B2: Source | C2: Predicted Relationship | D2: Actual Relationship | E2: Shared DNA | F2: Common Male Ancestor | G2: Common Female Ancestor | H2: Relationship to Ancestor | I2: My Ancestry | J2: Matched Ancestry
A3: Moira Monteith | B3: Ancestry | C3: 3rd-4th Cousin | D3: 3rd Cousin | E3: 108cM | F3: James Bevers | G3: Jane Beavers | H3: 2G Grandparents | I3: Mary Ann Bevers | J3: Walter Bevers
E4: 55cM | I4: Elsie Wilson | J4: Kate Bevers
I5: Gordon Walter Robertson | J5: Betty Last
I6: Simon Leigh Robertson | J6: Moira C Feeney
A7: Ted Hill | B7: Ancestry | C7: 3rd-4th Cousin | D7: 3rd Cousin | E7: 100cM | F7: James Bevers | G7: Jane Beavers | H7: 2G Grandparents | I7: Mary Ann Bevers | J7: Phoebe Beavis
I8: Elsie Wilson | J8: Edward Gill
I9: Gordon Walter Robertson | J9: Ruth Irene Gill
I10: Simon Leigh Robertson | J10: Ted Hill
A11: Gail Mason | B11: MyHeritage | C11: 3rd-5th Cousin | D11: 5th Cousin 1xremoved | E11: 63.9cM | F11: Thomas Bevis | G11: Susannah Argent | H11: 4G Grandparents | I11: James Beavers | J11: John Bevis
E12: 21.5cM | I12: Jane Beavers | J12: Elizabeth Bevis
I13: Mary Anne Beavis | J13: James Frost
I14: Elsie Wilson | J14: Katie Frost
I15: Gordon Walter Robertson | J15: Kenneth J Mason
I16: Simon Leigh Robertson | J16: Gail Mason
A17: Hilary Earl | B17: Ancestry | C17: 4th-6th Cousin | D17: 3rd Cousin 1xremoved | E17: 63cM | F17: James Bevers | G17: Jane Bevers | H17: 2G Grandparents | I17: Mary Ann Bevers | J17: James Beavers
E18: 35cM | I18: Elsie Wilson | J18: George James Beavers
I19: Gordon Walter Robertson | J19: Harold Walter Beavers
I20: Simon Leigh Robertson | J20: Ena Jose Bevers
J21: Hilary J Synder
A22: karenis1234 | B22: Ancestry | C22: 5th-8th Cousin | D22: 3rd Cousin | E22: 47cM | F22: James Bevers | G22: Jane Bevers | H22: 2G Grandparents | I22: Mary Ann Bevers | J22: Phobe Bevers
E23: 19cM | I23: Elsie Wilson | J23: Edward Gill
I24: Gordon Walter Robertson | J24: Beevers Edward Gill
I25: Simon Leigh Robertson | J25: Karen Gill
A26: Susan Jorgensen | B26: MyHeritage | C26: 5th-8th Cousin | D26: 5th Cousin 2xremoved | E26: 45cM | F26: Thomas Bevis | G26: Susannah Argent | H26: 4G Grandparents | I26: James Beavers | J26: John Bevis
I27: Jane Beavers | J27: Mary Beavis
I28: Mary Anne Beavis | J28: Susanna Brown
I29: Elsie Wilson | J29: Charles William Baldwin
I30: Gordon Walter Robertson | J30: Alice Edna Baldwin
I31: Simon Leigh Robertson | J31: Alice E Wilson
J32: Susan Wilson
A33: DEMARCSI | B33: Ancestry | C33: 5th-8th Cousin | D33: 5th Cousin | E33: 42cM | F33: Thomas Bevis | G33: Susannah Argent | H33: 4G Grandparents | I33: James Beavers | J33: John Bevis
E34: 19cM | I34: Jane Beavers | J34: Elizabeth Bevis
I35: Mary Anne Beavis | J35: William Frost
I36: Elsie Wilson | J36: William Frost
I37: Gordon Walter Robertson | J37: Harold Freeman Frost
I38: Simon Leigh Robertson | J38: Richard M Frost
A39: Miriam Roberts | B39: Ancestry | C39: 5th-8th Cousin | D39: 5th Cousin | E39: 42cM | F39: Thomas Bevis | G39: Susannah Argent | H39: 4G Grandparents | I39: James Beavers | J39: John Bevis
I40: Jane Beavers | J40: Susannah Beavis
...

Sheet Biddle
A1: Summary | B1: =COUNTIF(I2:I1170,C1)+COUNTIF(I2:I1170,D1) -> 35 | C1: Simon Leigh Robertson | D1: Jill Elaine Robertson
A2: Name | B2: Source | C2: Predicted Relationship | D2: Actual Relationship | E2: Shared DNA | F2: Common Male Ancestor | G2: Common Female Ancestor | H2: Relationship to Ancestor | I2: My Ancestry | J2: Matched Ancestry
A3: Alan Bottell | B3: Ancestry | C3: 4th-6th Cousin | D3: 5th Cousin 1xremoved | E3: 42cM | F3: John Biddle | G3: Ann Dadley | H3: 4G Grandparents | I3: George Biddle | J3: Thomas Biddle
E4: 29cM | I4: Emma Biddle | J4: Ruth Biddle
I5: Emily Elizabeth Patrick | J5: James Berry
I6: Walter William Robertson | J6: Charlotte Emily Berry
I7: Gordon Walter Robertson | J7: George Herbert Bottle
I8: Simon Leigh Robertson | J8: William John Bottle
J9: Alan Bottle
A10: sarabottell | B10: Ancestry | C10: 4th-6th Cousin | D10: 5th Cousin 2xremoved | E10: 37cM | F10: John Biddle | G10: Ann Dadley | H10: 4G Grandparents | I10: George Biddle | J10: Thomas Biddle
E11: 21cM | I11: Emma Biddle | J11: Ruth Biddle
I12: Emily Elizabeth Patrick | J12: James Berry
I13: Walter William Robertson | J13: Charlotte Emily Berry
I14: Gordon Walter Robertson | J14: George Herbert Bottle
I15: Simon Leigh Robertson | J15: William John Bottle
J16: Albert J Bottell
J17: Sara Louise Bottell
A18: Barbara Short | B18: Ancestry | C18: 5th-8th Cousin | D18: 5th Cousin | E18: 7cM | F18: John Biddle | G18: Anne Dadley | H18: 5G Grandparents | I18: George Biddle | J18: Thomas Biddle
E19: 29cM | I19: Emma Biddle | J19: Ruth Biddle
I20: Emily Elizabeth Patrick | J20: James Berry
I21: Walter William Robertson | J21: Charlotte Emily Berry
I22: Gordon Walter Robertson | J22: George Herbert Bottle
I23: Simon Leigh Robertson | J23: Elizabeth M Bottle
J24: Barbara M Harvey
A25: Christine Ford | B25: Ancestry | C25: 5th-8th Cousin | D25: 4th Cousin | E25: 28cM | F25: George Biddle | G25: Harriet Isabella Sims | H25: 3G Grandparents | I25: Emma Biddle | J25: James Biddle
I26: Emily Elizabeth Patrick | J26: Alexander J Biddle
I27: Walter William Robertson | J27: George Thomas Biddle
I28: Gordon Walter Robertson | J28: Lilian Violet Biddle
I29: Simon Leigh Robertson | J29: Christine Mitchell
A30: Patricia Nugent | B30: Ancestry | C30: 5th-8th Cousin | D30: 5th Cousin | E30: 27cM | F30: John Biddle | G30: Anne Dadley | H30: 5G Grandparents | I30: George Biddle | J30: Richard Biddle
E31: 13cM | I31: Emma Biddle | J31: Jane Biddle
I32: Emily Elizabeth Patrick | J32: George Bluck
I33: Walter William Robertson | J33: Francis W Bluck
I34: Gordon Walter Robertson | J34: Beatrice L Bluck
I35: Simon Leigh Robertson | J35: Patricia Nugent
A36: Roger Geoffrey Farrer | B36: MyHeritage | C36: 3rd-5th Cousin | D36: 5th Cousin | E36: 26.2cM | F36: John Biddle | G36: Anne Dadley | H36: 4G Grandparents | I36: George Biddle | J36: Thomas Biddle
I37: Emma Biddle | J37: Daniel Biddle
I38: Emily Elizabeth Patrick | J38: Hannah Maria Biddle
I39: Elsie Wilson | J39: Bernard Eric Farrer
I40: Gordon Walter Robertson | J40: Bernard Humphrey Penfold Farrer
...

Sheet Bing
A1: Summary | B1: =COUNTIF(I2:I1067,C1)+COUNTIF(I2:I1067,D1) -> 1 | C1: Simon Leigh Robertson | D1: Jill Elaine Robertson
A2: Name | B2: Source | C2: Predicted Relationship | D2: Actual Relationship | E2: Shared DNA | F2: Common Male Ancestor | G2: Common Female Ancestor | H2: Relationship to Ancestor | I2: My Ancestry | J2: Matched Ancestry
A3: Marc Dilnutt | B3: Ancestry | C3: 5th-8th Cousin | D3: 10th Cousin 2xremoved | E3: 12cM | F3: Henry Bing | G3: Susan Symons | H3: 9G Grandparents | I3: John Bing | J3: Henry Bing
E4: 10cM | I4: Thomas Bing | J4: Henry Bing
I5: Thomas Bing | J5: John Bing
I6: Sarah Bing | J6: Henry Bing
I7: Joseph Dierson Mercer | J7: Ann Bing
I8: Eliza Mercer | J8: John Greenstreet
I9: Anne Bushell | J9: John Greenstreet
I10: Ellen Jezzard | J10: Mary Ann Greenstreet
I11: Jack Tucker | J11: Eve Sarah Taylor
I12: June Margery Hall | J12: Leslie Frank May
I13: Simon Leigh Robertson | J13: Vera Dorothy May
J14: Christopher R Dilnutt
J15: Marc Richard Dilnutt

Sheet Bloomfield
A1: Summary | B1: =COUNTIF(I2:I1173,C1)+COUNTIF(I2:I1173,D1) -> 22 | C1: Simon Leigh Robertson | D1: Jill Elaine Robertson
A2: Name | B2: Source | C2: Predicted Relationship | D2: Actual Relationship | E2: Shared DNA | F2: Common Male Ancestor | G2: Common Female Ancestor | H2: Relationship to Ancestor | I2: My Ancestry | J2: Matched Ancestry
A3: Edward Miller | B3: Ancestry | C3: 5th-8th Cousin | D3: 8th Cousin 1xRemoved | E3: 21cM | F3: Isaac Bloomfield | G3: Hannah Whitan | H3: 7G Grandparents | I3: Edward Bloomfield | J3: John Bloomfield
E4: 7cM | I4: Susanna Bloomfield | J4: John Bloomfield
I5: George Otley | J5: Hannah Bloomfield
I6: Elizabeth Otley | J6: Jane Easter
I7: Samuel Alfred Brinkley | J7: Julian Smith
I8: Charlotte Lydia Brinkley | J8: Herbert Henry Smith
I9: Maud Bessie Hall | J9: Mabel Edna Smith
I10: June Margery Hall | J10: Anthony R Chattan
I11: Simon Leigh Robertson | J11: Jennifer M Chattan
J12: Edward Daniel Miller
A13: B.H. | B13: Ancestry | C13: 5th-8th Cousin | D13: 7th Cousin | E13: 17cM | F13: Edward Bloomfield | G13: Honour Page | H13: 6G Grandparents | I13: Susanna Bloomfield | J13: George Bloomfield
E14: 12cM | I14: George Otley | J14: James E Bloomfield
I15: Elizabeth Otley | J15: Lydia Bloomfield
I16: Samuel Alfred Brinkley | J16: Sarah Bowers
I17: Charlotte Lydia Brinkley | J17: Laura Ellen Horsley
I18: Maud Bessie Hall | J18: Joseph Ernest Topham
I19: June Margery Hall | J19: Ivan Vergene Topham
I20: Simon Leigh Robertson | J20: B Topham
A21: Kris Steele | B21: Ancestry | C21: 5th-8th Cousin | D21: 7th Cousin | E21: 17cM | F21: Edward Bloomfield | G21: Honour Page | H21: 6G Grandparents | I21: Susanna Bloomfield | J21: George Bloomfield
I22: George Otley | J22: James E Bloomfield
I23: Elizabeth Otley | J23: Lydia Bloomfield
I24: Samuel Alfred Brinkley | J24: Sarah Bowers
I25: Charlotte Lydia Brinkley | J25: Arthur William Horsley
I26: Maud Bessie Hall | J26: William Watts Horsley
I27: June Margery Hall | J27: Arthur William Horsley
I28: Simon Leigh Robertson | J28: Kris Horsley
A29: Andrea Piquette | B29: Ancestry | C29: 5th-8th Cousin | D29: 7th Cousin | E29: 17cM | F29: Edward Bloomfield | G29: Honour Page | H29: 6G Grandparents | I29: Susanna Bloomfield | J29: George Bloomfield
I30: George Otley | J30: James E Bloomfield
I31: Elizabeth Otley | J31: John Bloomfield
I32: Samuel Alfred Brinkley | J32: James Henry Bloomfield
I33: Charlotte Lydia Brinkley | J33: Randolph Bloomfield
I34: Maud Bessie Hall | J34: Jean Margaret Bloomfield
I35: June Margery Hall | J35: Locke
I36: Simon Leigh Robertson | J36: Andrea
A37: tbonebetty | B37: Ancestry | C37: 5th-8th Cousin | D37: 7th Cousin | E37: 17cM | F37: Edward Bloomfield | G37: Honour Page | H37: 6G Grandparents | I37: Susanna Bloomfield | J37: George Bloomfield
I38: George Otley | J38: James E Bloomfield
I39: Elizabeth Otley | J39: Lydia Bloomfield
I40: Samuel Alfred Brinkley | J40: Sarah Bowers
...

Sheet Boreham
A1: Summary | B1: =COUNTIF(I2:I1093,C1)+COUNTIF(I2:I1093,D1) -> 16 | C1: Simon Leigh Robertson | D1: Jill Elaine Robertson
A2: Name | B2: Source | C2: Predicted Relationship | D2: Actual Relationship | E2: Shared DNA | F2: Common Male Ancestor | G2: Common Female Ancestor | H2: Relationship to Ancestor | I2: My Ancestry | J2: Matched Ancestry
A3: Wendy Corkett | B3: MyHeritage | C3: 3rd-4th Cousin | D3: 3rd Cousin 1xremoved | E3: 77.6cM | F3: Joseph Boreham | G3: Hannah Rayner | H3: 3G Grandparents | I3: Hannah Agnes Boreham | J3: Alfred Charles Boreham
I4: Clifford William Wilson | J4: Frederick Cyril Boreham
I5: Elsie Wilson | J5: Ivy Phyllis Boreham
I6: Gordon Walter Robertson | J6: Wendy J Harden
I7: Simon Leigh Robertson
A8: Meg Fahey | B8: MyHeritage | C8: 3rd-5th Cousin | D8: 4th Cousin 1xremoved | E8: 52.2cM | F8: Joseph Boreham | G8: Hannah Rayner | H8: 3G Grandparents | I8: Hannah Agnes Boreham | J8: Alfred Charles Boreham
E9: 10cM | I9: Clifford William Wilson | J9: Frederick Cyril Boreham
I10: Elsie Wilson | J10: Ruby Alice Boreham
I11: Gordon Walter Robertson | J11: Colin R Trollope
I12: Simon Leigh Robertson | J12: Karen Anne Trollope
J13: Meg Fahey
A14: David Wallace | B14: MyHeritage | C14: 5th-8th Cousin | D14: 5th Cousin | E14: 34cM | F14: Jasper Boreham | G14: Susanna Camp | H14: 4G Grandparents | I14: Joseph Boreham | J14: Elizabeth Boreham
A15: Dave Wallace | B15: Ancestry | I15: Hannah Agnes Boreham | J15: Charles Mynett
I16: Clifford William Wilson | J16: Samuel Mynett
I17: Elsie Wilson | J17: Gladys Mary Mynett
I18: Gordon Walter Robertson | J18: David J Wallace
I19: Simon Leigh Robertson
A20: Tim Jee | B20: MyHeritage | C20: 5th-8th Cousin | D20: 5th Cousin | E20: 27cM | F20: Jasper Boreham | G20: Susanna Camp | H20: 4G Grandparents | I20: Joseph Boreham | J20: Elizabeth Boreham
I21: Hannah Agnes Boreham | J21: Charles Mynett
I22: Clifford William Wilson | J22: Samuel Mynett
I23: Elsie Wilson | J23: Gladys Mary Mynett
I24: Gordon Walter Robertson | J24: Wendy Mary Pratt
I25: Simon Leigh Robertson | J25: Tim Jee
A26: MRWeitkamp | B26: Ancestry | C26: 4th-6th Cousin | D26: 3rd Cousin 1xremoved | E26: 26cM | F26: Joseph Boreham | G26: Hannah Rayner | H26: 3G Grandparents | I26: Hannah Agnes Boreham | J26: Alfred Charles Boreham
I27: Clifford William Wilson | J27: Julia Emmeline Boreham
I28: Elsie Wilson | J28: Marion Faith Bicknell
I29: Gordon Walter Robertson | J29: Margaret Rosemary Burrows
I30: Simon Leigh Robertson
A31: Michelle Bryan | B31: Ancestry | C31: 4th-6th Cousin | D31: 4th Cousin 1xremoved | E31: 26cM | F31: Joseph Boreham | G31: Hannah Rayner | H31: 3G Grandparents | I31: Hannah Agnes Boreham | J31: Alfred Charles Boreham
I32: Clifford William Wilson | J32: Rosina J Boreham
I33: Elsie Wilson | J33: Florence Maud Eley
I34: Gordon Walter Robertson | J34: Marie K E Scutchings
I35: Simon Leigh Robertson | J35: Michael R Thorpe
J36: Michelle Nicola Thorpe
A37: dkspittle1 | B37: Ancestry | C37: 4th-6th Cousin | D37: 4th Cousin | E37: 24cM | F37: Joseph Boreham | G37: Hannah Rayner | H37: 3G Grandparents | I37: Hannah Agnes Boreham | J37: William Rayner Boreham
I38: Clifford William Wilson | J38: William T Boreham
I39: Elsie Wilson | J39: Amy Jean Boreham
I40: Gordon Walter Robertson | J40: Gillian Agnes Edgard
...

Sheet Brinkley
A1: Summary | B1: =COUNTIF(I2:I1147,C1)+COUNTIF(I2:I1147,D1) -> 43 | C1: Simon Leigh Robertson | D1: Jill Elaine Robertson
A2: Name | B2: Source | C2: Predicted Relationship | D2: Actual Relationship | E2: Shared DNA | F2: Common Male Ancestor | G2: Common Female Ancestor | H2: Relationship to Ancestor | I2: My Ancestry | J2: Matched Ancestry | K2: INDEX
A3: Caroline Marsh | B3: Ancestry | C3: 4th-6th Cousin | D3: 4th Cousin | E3: 33cM | F3: Samuel Brinkley | G3: Elizabeth Otley | H3: 3G Grandparents | I3: Samuel Alfred Brinkley | J3: John O Brinkley | K3: {=_xlfn._xlws.SORT(_xlfn.UNIQUE(_xlfn._xlws.FILTER(J:J, J:J <> "")))} -> #VALUE!
E4: 50cM | I4: Charlotte Lydia Brinkley | J4: Louisa Sarah Brinkley
I5: Maud Bessie Hall | J5: Pretoria May Hawes
I6: June Margery Hall | J6: Myrtle Edith V Bennett
I7: Simon Leigh Robertson | J7: Caroline Springings
A8: W.P. | B8: Ancestry | C8: 4th-6th Cousin | D8: 3rd Cousin 1xremoved | E8: 34cM | F8: Samuel Brinkley | G8: Elizabeth Otley | H8: 3G Grandparents | I8: Samuel Alfred Brinkley | J8: Ellen Maria Brinkley | K8: {=_xlfn._xlws.SORT(_xlfn.UNIQUE(_xlfn._xlws.FILTER(J:J, J:J <> "")))} -> A Williams
E9: 24cM | I9: Charlotte Lydia Brinkley | J9: Elsie E Foreman | K9: Abraham Brinkley
I10: Maud Bessie Hall | J10: Charles Kelt | K10: Ada Jane Balls
I11: June Margery Hall | J11: Male Skelt | K11: Alan Frank Youngman
I12: Simon Leigh Robertson | K12: Alfred Arthur John King
A13: Baron Glossop | B13: MyHeritage | C13: 4th-6th Cousin | D13: 3rd Cousin 1xremoved | E13: 32cM | F13: Samuel Brinkley | G13: Elizabeth Otley | H13: 3G Grandparents | I13: Samuel Alfred Brinkley | J13: John O Brinkley | K13: Alice Elsden
I14: Charlotte Lydia Brinkley | J14: Louisa Sarah Brinkley | K14: Alice Maud Bean
I15: Maud Bessie Hall | J15: Edith Emma Hawes | K15: Alice Ranson
I16: June Margery Hall | J16: Violet M Kirkby | K16: Amelia Ann Brooks
I17: Simon Leigh Robertson | J17: Barron Glossop | K17: Angela J Moore
A18: JRM01 | B18: Ancestry | C18: 5th-8th Cousin | D18: 4th Cousin 1xremoved | E18: 30cM | F18: William Brinkley | G18: Elizabeth Ruddock | H18: 4G Grandparents | I18: Samuel Brinkley | J18: Mary Brinkley | K18: Ann Brinkley
E19: 13cM | I19: Samuel Alfred Brinkley | J19: John Balls | K19: Barbara Joan Blow
I20: Charlotte Lydia Brinkley | J20: Ada Jane Balls | K20: Barbara Joan Elcome
I21: Maud Bessie Hall | J21: Rose Anne Frost | K21: Barron Glossop
I22: June Margery Hall | J22: June R Williams | K22: Beersheba Brinkley
I23: Simon Leigh Robertson | K23: Benjamin Brinkley
A24: Gareth Young | B24: Ancestry | C24: 4th-6th Cousin | D24: 4th Cousin 1xremoved | E24: 28cM | F24: Samuel Brinkley | G24: Elizabeth Otley | H24: 3G Grandparents | I24: Samuel Alfred Brinkley | J24: Samuel James Brinkley | K24: Buford Eugene Edison
E25: 9cM | I25: Charlotte Lydia Brinkley | J25: Walter Brinkley | K25: Capt William Brinkley
I26: Maud Bessie Hall | J26: Sidney Charles Brinkley | K26: Caroline Springings
I27: June Margery Hall | J27: Molly Kathleen Brinkley | K27: Cater B Brinkley
I28: Simon Leigh Robertson | J28: Deborah K Bowers | K28: Celia Ann Newport
J29: Gareth David Young | K29: Charles Kelt
A30: Kayla Burke | B30: Ancestry | C30: 4th-6th Cousin | D30: 4th Cousin | E30: 27cM | F30: Samuel Brinkley | G30: Elizabeth Otley | H30: 3G Grandparents | I30: Samuel Alfred Brinkley | J30: Ellen Maria Brinkley | K30: Claire Rebecca Townsend
E31: 17cM | I31: Charlotte Lydia Brinkley | J31: James John Foreman | K31: Clara Borley
I32: Maud Bessie Hall | J32: Elsie E Foreman | K32: Colin S T Bosher
I33: June Margery Hall | J33: Female Lloyd | K33: Colin Strangward
I34: Simon Leigh Robertson | J34: Kayla Burke | K34: Constance Stella Balls
A35: kevanfrost | B35: Ancestry | C35: 4th-6th Cousin | D35: 5th Cousin | E35: 25cM | F35: William Brinkley | G35: Elizabeth Ruddock | H35: 4G Grandparents | I35: Samuel Brinkley | J35: Mary Brinkley | K35: Daniel Brinkley
E36: 18cM | I36: Samuel Alfred Brinkley | J36: John Balls | K36: Darren James Newport
I37: Charlotte Lydia Brinkley | J37: Ada Jane Balls | K37: David Edward Newport
I38: Maud Bessie Hall | J38: Thomas William Frost | K38: David John Williams
I39: June Margery Hall | J39: Male Frost | K39: Deborah K Bowers
I40: Simon Leigh Robertson | J40: Kevan N Frost | K40: Doreen Joyce Blow
...

Sheet Bushell
A1: Summary | B1: =COUNTIF(I2:I1116,C1)+COUNTIF(I2:I1116,D1) -> 28 | C1: Simon Leigh Robertson | D1: Jill Elaine Robertson
A2: Name | B2: Source | C2: Predicted Relationship | D2: Actual Relationship | E2: Shared DNA | F2: Common Male Ancestor | G2: Common Female Ancestor | H2: Relationship to Ancestor | I2: My Ancestry | J2: Matched Ancestry
A3: Karen Frances McMahon | B3: MyHeritage | C3: 3rd-5th Cousin | D3: 5th Cousin | E3: 37cM | F3: John Maxted Bushell | G3: Mary Pittock | H3: 4G Grandparents | I3: Thomas Bushell | J3: William Bushell
E4: 20cM | I4: Anne Bushell | J4: Mary Jane Bushell
I5: Ellen Jezzard | J5: Horace J Coleman
I6: Jack Tucker | J6: Lilian Irene M Coleman
I7: June Margery Hall | J7: Mary Louisa Wait
I8: Simon Leigh Robertson | J8: Karen F Mitchell
A9: Wittber | B9: MyHeritage | C9: 3rd-5th Cousin | D9: 5th Cousin 1xremoved | E9: 32cM | F9: John Maxted Bushell | G9: Mary Pittock | H9: 4G Grandparents | I9: Thomas Bushell | J9: William Bushell
I10: Anne Bushell | J10: Mary Jane Bushell
I11: Ellen Jezzard | J11: Horace J Coleman
I12: Jack Tucker | J12: Lilian Irene M Coleman
I13: June Margery Hall | J13: Mary Louisa Wait
I14: Simon Leigh Robertson | J14: Mitchell
J15: Judith Lillian Witber
A16: Claire Coleman | B16: Ancestry | C16: 3rd-5th Cousin | D16: 5th Cousin 1xremoved | E16: 30cM | F16: John Maxted Bushell | G16: Mary Pittock | H16: 4G Grandparents | I16: Thomas Bushell | J16: William Bushell
I17: Anne Bushell | J17: Mary Jane Bushell
I18: Ellen Jezzard | J18: Harry Walter Coleman
I19: Jack Tucker | J19: Clifford Cecil Coleman
I20: June Margery Hall | J20: Kenneth G Coleman
I21: Simon Leigh Robertson | J21: Male Coleman
J22: Claire Coleman
A23: Sarah Leonard | B23: MyHeritage | C23: 3rd-5th Cousin | D23: 4th Cousin | E23: 28.9cM | F23: Thomas Bushell | G23: Eliza Mercer | H23: 3G Grandparents | I23: Anne Bushell | J23: Alfred Bushell
I24: Ellen Jezzard | J24: Charles John Bushell
I25: Jack Tucker | J25: Ellen Elizabeth Bushell
I26: June Margery Hall | J26: Albert E Leonard
I27: Simon Leigh Robertson | J27: Sarah Ellen Leonard
A28: Craig Coleman | B28: MyHeritage | C28: 3rd-5th Cousin | D28: 5th Cousin | E28: 27cM | F28: John Maxted Bushell | G28: Mary Pittock | H28: 4G Grandparents | I28: Thomas Bushell | J28: William Bushell
E29: 22cM | I29: Anne Bushell | J29: Mary Jane Bushell
I30: Ellen Jezzard | J30: Horace J Coleman
I31: Jack Tucker | J31: Harold John Coleman
I32: June Margery Hall | J32: Ronald Horace Coleman
I33: Simon Leigh Robertson | J33: Craig Stephen Coleman
A34: Dolly1914 | B34: Ancestry | C34: 5th-8th Cousin | D34: 3rd Cousin 1xremoved | E34: 24cM | F34: Thomas Bushell | G34: Eliza Mercer | H34: 3G Grandparents | I34: Anne Bushell | J34: Ellen Bushell
E35: 20cM | I35: Ellen Jezzard | J35: Alice Jane High
I36: Jack Tucker | J36: Alice Ellen A Potts
I37: June Margery Hall | J37: Dolly Cook
I38: Simon Leigh Robertson
A39: Colin Britchford | B39: Ancestry | C39: 5th-8th Cousin | D39: 9th Cousin 1xRemoved | E39: 23cM | F39: Richard Thomas Bushell | G39: Mary Cooke | H39: 9G Grandparents | I39: Edward Bushell | J39: Richard Bushell
E40: 19cM | I40: John Bushell | J40: Henry Bushell
...

Sheet Camp
A1: Summary | B1: =COUNTIF(I2:I1067,C1)+COUNTIF(I2:I1067,D1) -> 2 | C1: Simon Leigh Robertson | D1: Jill Elaine Robertson
A2: Name | B2: Source | C2: Predicted Relationship | D2: Actual Relationship | E2: Shared DNA | F2: Common Male Ancestor | G2: Common Female Ancestor | H2: Relationship to Ancestor | I2: My Ancestry | J2: Matched Ancestry
A3: sambrown_consultancy | B3: Ancestry | C3: 5th-8th Cousin | D3: 6th Cousin | E3: 14cM | F3: George Camp | G3: Mary Ann Eldred | H3: 5G Grandparents | I3: Susanna Camp | J3: Joshua Camp
I4: Joseph Boreham | J4: Sarah Camp
I5: Hannah Agnes Boreham | J5: George Thomas Camp
I6: Clifford William Wilson | J6: Frederick George Camp
I7: Elsie Wilson | J7: Alfred Charles Camp
I8: Gordon Walter Robertson | J8: Female Camp
I9: Simon Leigh Robertson | J9: Sam Youens
A10: Janet Fife | B10: Ancestry | C10: 5th-8th Cousin | D10: 6th Cousin | E10: 6cM | F10: George Camp | G10: Mary Ann Eldred | H10: 5G Grandparents | I10: Susanna Camp | J10: Mary D Camp
I11: Joseph Boreham | J11: Sophia Turner
I12: Hannah Agnes Boreham | J12: David Havers
I13: Clifford William Wilson | J13: Emma Havis
I14: Elsie Wilson | J14: William Wilkinson
I15: Gordon Walter Robertson | J15: Joan Edith Wilkinson
I16: Simon Leigh Robertson | J16: Janet Fife

Sheet Collins
A1: Summary | B1: =COUNTIF(I2:I1067,C1)+COUNTIF(I2:I1067,D1) -> 11 | C1: Simon Leigh Robertson | D1: Jill Elaine Robertson
A2: Name | B2: Source | C2: Predicted Relationship | D2: Actual Relationship | E2: Shared DNA | F2: Common Male Ancestor | G2: Common Female Ancestor | H2: Relationship to Ancestor | I2: My Ancestry | J2: Matched Ancestry
A3: Jade Crawford | B3: Ancestry | C3: 5th-8th Cousin | D3: 5th Cousin 1Xremoved | E3: 28cM | F3: James Collins | G3: Elizabeth Atkins | H3: 4G Grandparents | I3: Charlotte Collins | J3: George Collins
I4: Charlotte Freemantle | J4: Olive Collins
I5: William John Tucker | J5: william Francis Pond
I6: Jack Tucker | J6: Frances Aimee Pond
I7: June Margery Hall | J7: Wendy F Miller
I8: Jill Elaine Robertson | J8: Male Mahoney
J9: Jade Mahoney
A10: Lily Russell | B10: MyHeritage | C10: 5th-8th Cousin | D10: 5th Cousin | E10: 17cM | F10: James Collins | G10: Elizabeth Atkins | H10: 4G Grandparents | I10: Charlotte Collins | J10: George Collins
I11: Charlotte Freemantle | J11: Charles Collins
I12: William John Tucker | J12: Martha Anne Collins
I13: Jack Tucker | J13: Francis John Young
I14: June Margery Hall | J14: Male Young
I15: Jill Elaine Robertson | J15: Lily Young
A16: kitkat48312 | B16: Ancestry | C16: 5th-8th Cousin | D16: 5th Cousin | E16: 14cM | F16: James Collins | G16: Elizabeth Atkins | H16: 4G Grandparents | I16: James Collins | J16: George Collins
I17: Charlotte Collins | J17: Charles Collins
I18: Charlotte Freemantle | J18: George Henry Collins
I19: William John Tucker | J19: Olive Irene Collins
I20: Jack Tucker | J20: Emily May Bye
I21: June Margery Hall | J21: Judith Behr
I22: Jill Elaine Robertson | J22: Kitkat Kiefiuk
A23: Donald Kiefiuk | B23: Ancestry | C23: 5th-8th Cousin | D23: 5th Cousin | E23: 13cM | F23: James Collins | G23: Elizabeth Atkins | H23: 4G Grandparents | I23: James Collins | J23: George Collins
I24: Charlotte Collins | J24: Charles Collins
I25: Charlotte Freemantle | J25: George Henry Collins
I26: William John Tucker | J26: Olive Irene Collins
I27: Jack Tucker | J27: Emily May Bye
I28: June Margery Hall | J28: Judith Behr
I29: Jill Elaine Robertson | J29: Donald E Kiefiuk
A30: nonibehr13 | B30: Ancestry | C30: 5th-8th Cousin | D30: 4th Cousin 1xremoved | E30: 13cM | F30: James Collins | G30: Elizabeth Atkins | H30: 4G Grandparents | I30: James Collins | J30: George Collins
I31: Charlotte Collins | J31: Charles Collins
I32: Charlotte Freemantle | J32: George Henry Collins
I33: William John Tucker | J33: Olive Irene Collins
I34: Jack Tucker | J34: Emily May Bye
I35: June Margery Hall | J35: Judith Behr
I36: Jill Elaine Robertson
A37: John D William | B37: Ancestry | C37: 5th-8th Cousin | D37: 4th Cousin 2xremoved | E37: 10cM | F37: James Collins | G37: Sarah Towns | H37: 5G Grandparents | I37: James Collins | J37: Martha Hannah Collins
I38: Charlotte Collins | J38: Anna Rolfe
I39: Charlotte Freemantle | J39: Clinton Dewitt Williams
I40: William John Tucker | J40: Arthur Prout Williams
...

Sheet Dadley
A1: Summary | B1: =COUNTIF(I2:I1083,C1)+COUNTIF(I2:I1083,D1) -> 1 | C1: Simon Leigh Robertson | D1: Jill Elaine Robertson
A2: Name | B2: Source | C2: Predicted Relationship | D2: Actual Relationship | E2: Shared DNA | F2: Common Male Ancestor | G2: Common Female Ancestor | H2: Relationship to Ancestor | I2: My Ancestry | J2: Matched Ancestry
A3: jennett11 | B3: Ancestry | C3: 4th-6th Cousin | D3: 6th Cousin | E3: 6cM | F3: John Dadley | G3: Catherine Gilbert | H3: 5G Grandparents | I3: Anne Dadley | J3: Henry Dadley
I4: George Biddle | J4: Mary Dadley
I5: Emma Biddle | J5: Elizabeth D Cattell
I6: Emily Elizabeth Patrick | J6: Sarah Stamps
I7: Walter William Robertson | J7: Laura Poulton
I8: Gordon Walter Robertson | J8: Mary Louisa Harman
I9: Simon Leigh Robertson | J9: Judith A Morley

Sheet Davis
A1: Summary | B1: =COUNTIF(I2:I1067,C1)+COUNTIF(I2:I1067,D1) -> 1 | C1: Simon Leigh Robertson | D1: Jill Elaine Robertson
A2: Name | B2: Source | C2: Predicted Relationship | D2: Actual Relationship | E2: Shared DNA | F2: Common Male Ancestor | G2: Common Female Ancestor | H2: Relationship to Ancestor | I2: My Ancestry | J2: Matched Ancestry
A3: cm706895 | B3: Ancestry | C3: 5th-8th Cousin | D3: 6th Cousin | E3: 8cM | F3: Edward Davis | H3: 5G Grandparents | I3: Mary Davis | J3: Evan Davis
I4: George Jezzard | J4: Eliza Davis
I5: George P Jezzard | J5: Margaret Bowles
I6: Ellen Jezzard | J6: John Arthur Sullivan
I7: John Francis Tucker | J7: Mary Helen Sullivan
I8: June Margery Hall | J8: Robert A Mc Cormick
I9: Simon Leigh Robertson | J9: C Mc Cormick

Sheet Dibel
A1: Summary | B1: =COUNTIF(I2:I1067,C1)+COUNTIF(I2:I1067,D1) -> 1 | C1: Simon Leigh Robertson | D1: Jill Elaine Robertson
A2: Name | B2: Source | C2: Predicted Relationship | D2: Actual Relationship | E2: Shared DNA | F2: Common Male Ancestor | G2: Common Female Ancestor | H2: Relationship to Ancestor | I2: My Ancestry | J2: Matched Ancestry
A3: Paul Breame | B3: Ancestry | C3: 5th-8th Cousin | D3: 7th Cousin 1xremoved | E3: 8cM | F3: John Dibel | G3: Mary West | H3: 8G Grandparents | I3: Mary Dibal | J3: Mary Dyball
I4: Benjamin Mayes | J4: Rose Ward
I5: Ann May | J5: James Burton
I6: Eliza Mercer | J6: Hannah Burton
I7: Anne Bushell | J7: William Breame
I8: Ellen Jezzard | J8: James W Breame
I9: Jack Tucker | J9: James Robert Breame
I10: June Margery Hall | J10: Paul R Breame
I11: Simon Leigh Robertson

Sheet Disdale
A1: Summary | B1: =COUNTIF(I2:I1087,C1)+COUNTIF(I2:I1087,D1) -> 4 | C1: Simon Leigh Robertson | D1: Jill Elaine Robertson
A2: Name | B2: Source | C2: Predicted Relationship | D2: Actual Relationship | E2: Shared DNA | F2: Common Male Ancestor | G2: Common Female Ancestor | H2: Relationship to Ancestor | I2: My Ancestry | J2: Matched Ancestry
A3: Brenda Whitmore | B3: Ancestry | C3: 4th Cousin | D3: 4th Cousin 1xRemoved | E3: 19cM | F3: John Disdale | G3: Mary Ann Noble | H3: 4G Grandparents | I3: Emma Disdale | J3: John Charles Disdale
E4: 19cM | I4: Susannah Shickle | J4: Robert Warner Disdale
I5: Charlotte Lydia Brinkley | J5: Reginald Robert Disdale
I6: Maud Bessie Hall | J6: Joan Lilian Disdale
I7: June Margery Hall | J7: Brenda S Bourchier
I8: Simon Leigh Robertson
A9: Jeffrey Leigh Miller | B9: Ancestry | C9: 5th-8th Cousin | D9: 6th Cousin | E9: 15cM | F9: Thomas Disdale | G9: Margaret Angier | H9: 5G Grandparents | I9: John Disdale | J9: Mary Disdale | K9: {=_xlfn._xlws.SORT(_xlfn.UNIQUE(J:J))} -> #VALUE!
I10: Emma Disdale | J10: Elizabeth Mayhew
I11: Susannah Shickle | J11: Elizabeth Olive Cook
I12: Charlotte Lydia Brinkley | J12: Alice Maud Lord
I13: Maud Bessie Hall | J13: Richard Maurice Cavill
I14: June Margery Hall | J14: Bette Jane Cavill
I15: Jill Elaine Robertson | J15: Jeffrey Leigh Miller
A16: mphelan122873 | B16: Ancestry | C16: 5th-8th Cousin | D16: 4th Cousin 2xremoved | E16: 14cM | F16: Thomas Disdale | G16: Ann Reynolds | H16: 5G Grandparents | I16: John Disdale | J16: Sarah Disdale | K16: {=_xlfn._xlws.SORT(_xlfn.UNIQUE(J:J))} -> Alice Maud Lord
I17: Emma Disdale | J17: Charles Sturgeon | K17: Bette Jane Cavill
I18: Susannah Shickle | J18: Charles M Sturgeon | K18: Brenda S Bourchier
I19: Charlotte Lydia Brinkley | J19: Mary E Sturgeon | K19: Charles M Sturgeon
I20: Maud Bessie Hall | J20: Michael Scott Phelan | K20: Charles Sturgeon
I21: June Margery Hall | K21: Edith May Cole
I22: Jill Elaine Robertson | K22: Elizabeth Mary Scott
A23: Jennifer Parry | B23: Ancestry | C23: 5th-8th Cousin | D23: 6th Cousin | E23: 8cM | F23: Thomas Disdale | G23: Margaret Angier | H23: 5G Grandparents | I23: John Disdale | J23: Sarah Angier | K23: Elizabeth Mayhew
I24: Emma Disdale | J24: Sarah Lawrence | K24: Elizabeth Olive Cook
I25: Susannah Shickle | J25: Elizabeth Mary Scott | K25: Ileana Edith Rowland
I26: Charlotte Lydia Brinkley | J26: William Cole | K26: Jeffrey Leigh Miller
I27: Maud Bessie Hall | J27: Edith May Cole | K27: Jennifer Roberts
I28: June Margery Hall | J28: Ileana Edith Rowland | K28: Joan Lilian Disdale
I29: Jill Elaine Robertson | J29: Jennifer Roberts | K29: John Charles Disdale
K30: Mary Disdale
K31: Mary E Sturgeon
K32: Matched Ancestry
K33: Michael Scott Phelan
K34: Reginald Robert Disdale
K35: Richard Maurice Cavill
K36: Robert Warner Disdale
K37: Sarah Angier
K38: Sarah Disdale
K39: Sarah Lawrence
K40: William Cole
...

Sheet Douglas
A1: Summary | B1: =COUNTIF(I2:I1087,C1)+COUNTIF(I2:I1087,D1) -> 3 | C1: Simon Leigh Robertson | D1: Jill Elaine Robertson
A2: Name | B2: Source | C2: Predicted Relationship | D2: Actual Relationship | E2: Shared DNA | F2: Common Male Ancestor | G2: Common Female Ancestor | H2: Relationship to Ancestor | I2: My Ancestry | J2: Matched Ancestry
A3: Carolyn Board | B3: Ancestry | C3: 5th-8th Cousin | D3: 4th Cousin | E3: 27cM | G3: Jean Douglas | H3: 3G Grandparents | I3: William Millar Robertson | J3: Jean Douglas Rutt
I4: Herbert Ernest Robertson | J4: Arthur Henry Blandford
I5: Walter William Robertson | J5: Stanley Robert Blandford
I6: Gordon Walter Robertson | J6: Anne Pauline Blandford
I7: Simon Leigh Robertson | J7: Carolyn Elizabeth Derrick
A8: Jonathan Derrick | B8: Ancestry | C8: 5th-8th Cousin | D8: 4th Cousin 1xremoved | E8: 21cM | G8: Jean Douglas | H8: 3G Grandparents | I8: William Millar Robertson | J8: Jean Douglas Rutt
I9: Herbert Ernest Robertson | J9: Arthur Henry Blandford
I10: Walter William Robertson | J10: Stanley Robert Blandford
I11: Gordon Walter Robertson | J11: Anne Pauline Blandford
I12: Simon Leigh Robertson | J12: Peter Anthony Derrick
J13: Jonathan Derrick
A14: Debbie Derrick | B14: Ancestry | C14: 5th-8th Cousin | D14: 4th Cousin | E14: 21cM | G14: Jean Douglas | H14: 3G Grandparents | I14: William Millar Robertson | J14: Jean Douglas Rutt
I15: Herbert Ernest Robertson | J15: Arthur Henry Blandford
I16: Walter William Robertson | J16: Stanley Robert Blandford
I17: Gordon Walter Robertson | J17: Anne Pauline Blandford
I18: Simon Leigh Robertson | J18: Deborah Anne Derrick

Sheet Dyason
A1: Summary | B1: =COUNTIF(I2:I1097,C1)+COUNTIF(I2:I1097,D1) -> 12 | C1: Simon Leigh Robertson | D1: Jill Elaine Robertson
A2: Name | B2: Source | C2: Predicted Relationship | D2: Actual Relationship | E2: Shared DNA | F2: Common Male Ancestor | G2: Common Female Ancestor | H2: Relationship to Ancestor | I2: My Ancestry | J2: Matched Ancestry
A3: Sheila Hartley | B3: MyHeritage | C3: 5th-8th Cousin | D3: 6th Cousin 3xremoved | E3: 25cM | F3: John Dyason | G3: Catherine Hampton | H3: 8G Grandparents | I3: Benjamin Dyason | J3: Joshua Dyason
I4: Elizabeth Dyason | J4: Joshua Dyason
I5: Sarah Bing | J5: John Dyason
I6: Joseph Dierson Mercer | J6: Joshua Dyason
I7: Eliza Mercer | J7: John Prescott Dyason
I8: Anne Bushell | J8: Myrtle Eliza Dyason
I9: Ellen Jezzard | J9: Sheila Mary Ferris
I10: Jack Tucker
I11: June Margery Hall
I12: Jill Elaine Robertson
A13: HMR | B13: MyHeritage | C13: 5th-8th Cousin | D13: 7th Cousin 2xremoved | E13: 25cM | F13: John Dyason | G13: Catherine Hampton | H13: 8G Grandparents | I13: Benjamin Dyason | J13: Joshua Dyason
I14: Elizabeth Dyason | J14: Joshua Dyason
I15: Sarah Bing | J15: John Dyason
I16: Joseph Dierson Mercer | J16: Joshua Dyason
I17: Eliza Mercer | J17: John Prescott Dyason
I18: Anne Bushell | J18: Myrtle Eliza Dyason
I19: Ellen Jezzard | J19: Sheila Mary Ferris
I20: Jack Tucker | J20: H M Roberts
I21: June Margery Hall
I22: Jill Elaine Robertson
A23: Sebastian Gauci | B23: MyHeritage | C23: 5th-8th Cousin | D23: 7th Cousin 1xremoved | E23: 24cM | F23: John Dyason | G23: Catherine Hampton | H23: 8G Grandparents | I23: Benjamin Dyason | J23: Joshua Dyason
I24: Elizabeth Dyason | J24: Joshua Dyason
I25: Sarah Bing | J25: John Dyason
I26: Joseph Dierson Mercer | J26: Joshua Dyason
I27: Eliza Mercer | J27: John Prescott Dyason
I28: Anne Bushell | J28: Myrtle Eliza Dyason
I29: Ellen Jezzard | J29: Sheila Mary Ferris
I30: Jack Tucker | J30: H M Roberts
I31: June Margery Hall | J31: Sebastian Gauci
I32: Jill Elaine Robertson
A33: Beverley Brigden | B33: MyHeritage | C33: 5th-8th Cousin | D33: 7th Cousin 1xremoved | E33: 16cM | F33: John Dyason | G33: Catherine Hampton | H33: 8G Grandparents | I33: Benjamin Dyason | J33: Joshua Dyason
I34: Elizabeth Dyason | J34: Elizabeth Dyason
I35: Sarah Bing | J35: Mary Dadd
I36: Joseph Dierson Mercer | J36: Sara Wood
I37: Eliza Mercer | J37: George Thomas Hogben
I38: Anne Bushell | J38: Sarah Mary Hogben
I39: Ellen Jezzard | J39: Norris Leslie Brigden
I40: Jack Tucker | J40: Beverley Brigden
...

Sheet Felton
A1: Summary | B1: =COUNTIF(I2:I1056,C1)+COUNTIF(I2:I1056,D1) -> 2 | C1: Simon Leigh Robertson | D1: Jill Elaine Robertson
A2: Name | B2: Source | C2: Predicted Relationship | D2: Actual Relationship | E2: Shared DNA | F2: Common Male Ancestor | G2: Common Female Ancestor | H2: Relationship to Ancestor | I2: My Ancestry | J2: Matched Ancestry
A3: Martin David | B3: Ancestry | C3: 5th-8th Cousin | D3: 6th Cousin | E3: 7cM | F3: Samuel Felton | G3: Mary Shorecroft | H3: 5G Grandparents | I3: Mary Jane Felton | J3: James Felton
I4: Hannah Rayner | J4: James Felton
I5: Hannah Agnes Boreham | J5: Alexander J Felton
I6: Clifford William Wilson | J6: Joseph Felton
I7: Elsie Wilson | J7: Joan M Felton
I8: Gordon Walter Robertson | J8: Michael George David
I9: Simon Leigh Robertson | J9: Martin David
A10: Martina David | B10: Ancestry | C10: 5th-8th Cousin | D10: 6th Cousin 1xremoved | E10: 6cM | F10: Samuel Felton | G10: Mary Shorecroft | H10: 5G Grandparents | I10: Mary Jane Felton | J10: James Felton
I11: Hannah Rayner | J11: James Felton
I12: Hannah Agnes Boreham | J12: Alexander J Felton
I13: Clifford William Wilson | J13: Joseph Felton
I14: Elsie Wilson | J14: Joan M Felton
I15: Gordon Walter Robertson | J15: Michael George David
I16: Simon Leigh Robertson | J16: Martin David
J17: Martina David

Sheet Field
A1: Summary | B1: =COUNTIF(I2:I1067,C1)+COUNTIF(I2:I1067,D1) -> 1 | C1: Simon Leigh Robertson | D1: Jill Elaine Robertson
A2: Name | B2: Source | C2: Predicted Relationship | D2: Actual Relationship | E2: Shared DNA | F2: Common Male Ancestor | G2: Common Female Ancestor | H2: Relationship to Ancestor | I2: My Ancestry | J2: Matched Ancestry
A3: Paul smith | B3: Ancestry | C3: 5th-8th Cousin | D3: 9th Cousin | E3: 7cM | F3: Thomas Field | G3: Sarah Boosey | H3: 8G Grandparents | I3: Susan Field | J3: Esther Field
I4: James Styliman | J4: Daniel Bright
I5: Mary Stylemen | J5: Jane Bright
I6: William Sams | J6: Sarah Harvey
I7: Sarah Sams | J7: Daniel Smith
I8: William Wilson | J8: Henry Willian Smith
I9: Clifford William Wilson | J9: Joseph Gilbert Smith
I10: Elsie Wilson | J10: John Gilbert Smith
I11: Gordon Walter Robertson | J11: Male Smith
I12: Simon Leigh Robertson | J12: Paul Richard Smith

Sheet Fooks
A1: Summary | B1: =COUNTIF(I2:I1079,C1)+COUNTIF(I2:I1079,D1) -> 7 | C1: Simon Leigh Robertson | D1: Jill Elaine Robertson
A2: Name | B2: Source | C2: Predicted Relationship | D2: Actual Relationship | E2: Shared DNA | F2: Common Male Ancestor | G2: Common Female Ancestor | H2: Relationship to Ancestor | I2: My Ancestry | J2: Matched Ancestry
A3: Iona Newell | B3: Ancestry | C3: 4th-6th Cousin | D3: 5th Cousin | E3: 26cM | F3: William Fooks | G3: Ann Dollen | H3: 4G Grandparents | I3: Mary Fooks | J3: Ann Fooks
I4: John Tucker | J4: Charles Oxenbury
I5: William John Tucker | J5: Walter James Oxenbury
I6: Jack Tucker | J6: Philip G Oxenbury
I7: June Margery Hall | J7: Ruth H Oxenbury
I8: Jill Elaine Robertson | J8: Iona Newell
A9: Ruth Newell | B9: Ancestry | C9: 4th-6th Cousin | D9: 4th Cousin 1xremoved | E9: 24cM | F9: William Fooks | G9: Ann Dollen | H9: 4G Grandparents | I9: Mary Fooks | J9: Ann Fooks
I10: John Tucker | J10: Charles Oxenbury
I11: William John Tucker | J11: Walter James Oxenbury
I12: Jack Tucker | J12: Philip G Oxenbury
I13: June Margery Hall | J13: Ruth H Oxenbury
I14: Jill Elaine Robertson
A15: georgier22 | B15: Ancestry | C15: 4th-6th Cousin | D15: 5th Cousin | E15: 16cM | F15: William Fooks | G15: Ann Dollen | H15: 4G Grandparents | I15: Mary Fooks | J15: Ann Fooks
E16: 21cM | I16: John Tucker | J16: Lawrence Oxenbury
I17: William John Tucker | J17: Jane Oxenbury
I18: Jack Tucker | J18: Victor Dan O Rossiter
I19: June Margery Hall | J19: Iris May Rossiter
I20: Jill Elaine Robertson | J20: Georgina W Reading
A21: Lynda Roberts | B21: MyHeritage | C21: 4th-6th Cousin | D21: 5th Cousin | E21: 20cM | F21: William Fooks | G21: Ann Dollen | H21: 4G Grandparents | I21: Mary Fooks | J21: Ann Fooks
I22: John Tucker | J22: Joseph Oxenbury
I23: William John Tucker | J23: Matilda F Oxenbury
I24: Jack Tucker | J24: Harry Lawrence Trease
I25: June Margery Hall | J25: Harry L T Grieg
I26: Jill Elaine Robertson | J26: Lynda Greigg
A27: Sarah Reynard | B27: Ancestry | C27: 5th-6th Cousin | D27: 5th Cousin 1xremoved | E27: 10cM | F27: William Fooks | G27: Ann Dollen | H27: 4G Grandparents | I27: Mary Fooks | J27: Ann Fooks
E28: 7cM | I28: John Tucker | J28: Lawrence Oxenbury
I29: William John Tucker | J29: Jane Oxenbury
I30: Jack Tucker | J30: Mabel M Rossiter
I31: June Margery Hall | J31: Donald J Oxenbury
I32: Simon Leigh Robertson | J32: Mary Janet Oxenbury
J33: Sarah Reynard
A34: CarmelJoan | B34: Ancestry | C34: 5th-6th Cousin | D34: 5th Cousin | E34: 9cM | F34: William Fooks | G34: Anne Mackenzie | H34: 4G Grandparents | I34: Mary Fooks | J34: Elizabeth Fooks
I35: John Tucker | J35: James Lipson
I36: William John Tucker | J36: Elizabeth Lipson
I37: Jack Tucker | J37: Kathleen Dwyer
I38: June Margery Hall | J38: John James Cross
I39: Simon Leigh Robertson | J39: Carmel Joan Cross
A40: Elizabeth Hardwick | B40: Ancestry | C40: 5th-6th Cousin | D40: 5th Cousin 1xremoved | E40: 7cM | F40: William Fooks | G40: Ann Dollen | H40: 4G Grandparents | I40: Mary Fooks | J40: Ann Fooks
...

Sheet Ford
A1: Summary | B1: =COUNTIF(I2:I1099,C1)+COUNTIF(I2:I1099,D1) -> 10 | C1: Simon Leigh Robertson | D1: Jill Elaine Robertson
A2: Name | B2: Source | C2: Predicted Relationship | D2: Actual Relationship | E2: Shared DNA | F2: Common Male Ancestor | G2: Common Female Ancestor | H2: Relationship to Ancestor | I2: My Ancestry | J2: Matched Ancestry
A3: Freya Brightwater | B3: Ancestry | C3: 4th-6th Cousin | D3: 6th Cousin 1xremoved | E3: 52cM | F3: Martin Ford | G3: Sarah Howard | H3: 5G Grandparents | I3: Male Ford | J3: Mary Ford
B4: MyHeritage | I4: Anne Ford | J4: James argent
I5: Henry Hall | J5: William Argent
I6: Frederick William Hall | J6: William Patrick Argent
I7: Maud Bessie Hall | J7: Albert William Argent
I8: June Margery Hall | J8: Brian D Argent
I9: Simon Leigh Robertson | J9: Deborah A Argent
J10: Freya L Brightwater
A11: Maria Oliver | B11: MyHeritage | C11: 4th-6th Cousin | D11: 6th Cousin 1xremoved | E11: 45cM | F11: Martin Ford | G11: Sarah Howard | H11: 5G Grandparents | I11: Male Ford | J11: Mary Ford
I12: Anne Ford | J12: William Argent
I13: Henry Hall | J13: Sarah Argent
I14: Frederick William Hall | J14: Henry Charles Taylor
I15: Maud Bessie Hall | J15: Sarah Annie Taylor
I16: June Margery Hall | J16: Jane Mary Gatfield
I17: Simon Leigh Robertson | J17: Terry Stacey
J18: Maria Stacey
A19: Jennifer Davis | B19: 23andme | C19: 4th-6th Cousin | D19: 6th Cousin 2xremoved | E19: 41cM | F19: Martin Ford | G19: Sarah Howard | H19: 5G Grandparents | I19: Male Ford | J19: Mary Ford
A20: Jennifer Davis | B20: MyHeritage | E20: 35cM | I20: Anne Ford | J20: William Argent
I21: Henry Hall | J21: Sarah Argent
I22: Frederick William Hall | J22: Henry Charles Taylor
I23: Maud Bessie Hall | J23: Sarah Annie Taylor
I24: June Margery Hall | J24: Louisa Annie Gatfield
I25: Simon Leigh Robertson | J25: Josephine D Hawes
J26: Male Davis
J27: Jennifer Davis
A28: Melissa Uhrin | B28: Ancestry | C28: 4th-6th Cousin | D28: 6th Cousin 2xremoved | E28: 26cM | F28: Martin Ford | G28: Sarah Howard | H28: 5G Grandparents | I28: Male Ford | J28: Mary Ford
I29: Anne Ford | J29: William Argent
I30: Henry Hall | J30: Sarah Argent
I31: Frederick William Hall | J31: Henry Charles Taylor
I32: Maud Bessie Hall | J32: Sarah Annie Taylor
I33: June Margery Hall | J33: Jane Mary Gatfield
I34: Simon Leigh Robertson | J34: Kenneth Stacey
J35: Female Stacey
J36: Melissa
A37: Terry Stacey | B37: Ancestry | C37: 4th-6th Cousin | D37: 6th Cousin | E37: 25cM | F37: Martin Ford | G37: Sarah Howard | H37: 5G Grandparents | I37: Male Ford | J37: Mary Ford
I38: Anne Ford | J38: William Argent
I39: Henry Hall | J39: Sarah Argent
I40: Frederick William Hall | J40: Henry Charles Taylor
...

Sheet Freemantle
A1: Summary | B1: =COUNTIF(I2:I1081,C1)+COUNTIF(I2:I1081,D1) -> 14 | C1: Simon Leigh Robertson | D1: Jill Elaine Robertson
A2: Name | B2: Source | C2: Predicted Relationship | D2: Actual Relationship | E2: Shared DNA | F2: Common Male Ancestor | G2: Common Female Ancestor | H2: Relationship to Ancestor | I2: My Ancestry | J2: Matched Ancestry 1 | K2: Matched Ancestry 2 | L2: Matched Ancestry 3 | M2: Matched Ancestry 4
A3: Briony Canning | B3: Ancestry | C3: 5th-8th Cousin | D3: 9th Cousin 1xremoved | E3: 17cM | F3: Jonathan Freemantle | G3: Susanna Bunny | H3: 8G Grandparents | I3: John Freemantle | J3: Thomas Freemantle
I4: John M Freemantle | J4: Thomas Freemantle
I5: Nicholas Freemantle | J5: Jonathan Freemantle
I6: Nicholas Freemantle | J6: James Freemantle
I7: James Freemantle | J7: John Freemantle
I8: Charlotte Freemantle | J8: Alfred Freemantle
I9: William John Tucker | J9: William K Freemantle
I10: Jack Tucker | J10: Gladys V Freemantle
I11: June Margery Hall | J11: Briony S Tillen
I12: Jill Elaine Robertson
A13: Pam Durham | B13: Ancestry | C13: 5th-8th Cousin | D13: 6th Cousin | E13: 16cM | F13: Nicholas Freemantle | G13: Sarah Logget | H13: 5G Grandparents | I13: Nicholas Freemantle | J13: Andrew Freemantle
I14: James Freemantle | J14: Henry Freemantle
I15: Charlotte Freemantle | J15: Ann Freemantle
I16: William John Tucker | J16: James Stubbington
I17: Jack Tucker | J17: Evelyn D Stubbington
I18: June Margery Hall | J18: Gwendoline Ruby Read
I19: Simon Leigh Robertson | J19: Pamela J Hockley
A20: Liam Freemantle | B20: My Heritage | C20: 5th-8th Cousin | D20: 9th Cousin | E20: 12cM | F20: Jonathan Freemantle | G20: Susanna Bunny | H20: 8G Grandparents | I20: John Freemantle | J20: Thomas Freemantle
I21: John M Freemantle | J21: Thomas Freemantle
I22: Nicholas Freemantle | J22: Jonathan Freemantle
I23: Nicholas Freemantle | J23: James Freemantle
I24: James Freemantle | J24: John Freemantle
I25: Charlotte Freemantle | J25: Alfred Freemantle
I26: William John Tucker | J26: William K Freemantle
I27: Jack Tucker | J27: Peter N M Freemantle
I28: June Margery Hall | J28: Peter J Freemantle
I29: Jill Elaine Robertson | J29: Liam James Freemantle
A30: Jamie Campbell | B30: Ancestry | C30: 5th-8th Cousin | D30: 6th Cousin | E30: 11cM | F30: William Freemantle | G30: Ann Cole | H30: 5G Grandparents | I30: Nicholas Freemantle | J30: James Freemantle
I31: James Freemantle | J31: Thomas Freemantle
I32: Charlotte Freemantle | J32: Thomas William Freemantle
I33: William John Tucker | J33: Rhoda F Freemantle
I34: Jack Tucker | J34: Sidney A Townsend
I35: June Margery Hall | J35: Female Townsend
I36: Simon Leigh Robertson | J36: Jamie Campbell
A37: Tammy Mclaughlin | B37: Ancestry | C37: 5th-8th Cousin | D37: 6th Cousin | E37: 11cM | F37: William Freemantle | G37: Ann Cole | H37: 5G Grandparents | I37: Nicholas Freemantle | J37: James Freemantle
I38: James Freemantle | J38: Thomas Freemantle
I39: Charlotte Freemantle | J39: Thomas William Freemantle
I40: William John Tucker | J40: Rhoda F Freemantle
...

Sheet Gates
A1: Summary | B1: =COUNTIF(I2:I1067,C1)+COUNTIF(I2:I1067,D1) -> 1 | C1: Simon Leigh Robertson | D1: Jill Elaine Robertson
A2: Name | B2: Source | C2: Predicted Relationship | D2: Actual Relationship | E2: Shared DNA | F2: Common Male Ancestor | G2: Common Female Ancestor | H2: Relationship to Ancestor | I2: My Ancestry | J2: Matched Ancestry
A3: Darryl Clark | B3: Ancestry | C3: 5th-8th Cousin | D3: 6th Cousin | E3: 9cM | F3: George Gates | G3: Elizabeth Worledge | H3: 5G Grandparents | I3: Elizabeth Gates | J3: Mary Ann Gates
I4: Elizabeth Otley | J4: Frederick Fincham
I5: Samuel Alfred Brinkley | J5: Louisa Fincham
I6: Charlotte Lydia Brinkley | J6: Alexander Archibald Beswick
I7: Maud Bessie Hall | J7: Archibald Beswick Payne
I8: June Margery Hall | J8: Female Payne
I9: Simon Leigh Robertson | J9: Darryl Clark

Sheet Hall
A1: Summary | B1: =COUNTIF(I2:I1171,C1)+COUNTIF(I2:I1171,D1) -> 36 | C1: Simon Leigh Robertson | D1: Jill Elaine Robertson
A2: Name | B2: Source | C2: Predicted Relationship | D2: Actual Relationship | E2: Shared DNA | F2: Common Male Ancestor | G2: Common Female Ancestor | H2: Relationship to Ancestor | I2: My Ancestry | J2: Matched Ancestry | K2: INDEX
A3: Debra Carter | B3: Ancestry | C3: 3rd-4th Cousin | D3: 2nd Cousin | E3: 265cM | F3: Frederick William Hall | G3: Charlotte Lydia Brinkley | H3: 1G Grandparents | I3: Maud Bessie Hall | J3: Florence Ida Hall | K3: {=_xlfn._xlws.SORT(_xlfn.UNIQUE(_xlfn._xlws.FILTER(J:J, J:J <> "")))} -> Alfred Banham
E4: 154cM | I4: June Margery Hall | J4: Barbara D Butters | K4: Amy Delmonte Hall
I5: Simon Leigh Robertson | J5: Debra Julie Carter | K5: Angela Boxall
A6: Cherish Maxwell | B6: 23andMe | C6: 3rd Cousin | D6: 2nd Cousin 1xremoved | E6: 112cM | F6: Frederick William Hall | G6: Charlotte Lydia Brinkley | H6: 1G Grandparents | I6: Maud Bessie Hall | J6: Ethel Christine Hall | K6: Ann E C Hall
I7: June Margery Hall | J7: Marian C Sporle | K7: Annie Kathleen Willis
I8: Simon Leigh Robertson | J8: Katrina Helen Mexson | K8: Anthony B Williams
J9: Cherish Maxwell | K9: April Faulkner
A10: llagasse140 | B10: Ancestry | C10: 3rd-4th Cousin | D10: Half 2nd Cousin | E10: 127cM | F10: Frederick William Hall | G10: Charlotte Lydia Brinkley | H10: 1G Grandparents | I10: Maud Bessie Hall | J10: Nellie Hall | K10: Arthur John Hall
E11: 110cM | G11: Olive Loffler | I11: June Margery Hall | J11: Stanley Autun Tattershall | K11: Banham
I12: Simon Leigh Robertson | J12: Lorraine Tattershall | K12: Barbara D Butters
A13: Kyle Short | B13: 23andMe | C13: 3rd Cousin | D13: Half 2nd Cousin 1xremoved | E13: 98cM | F13: Frederick William Hall | G13: Charlotte Lydia Brinkley | H13: 1G Grandparents | I13: Maud Bessie Hall | J13: Nellie Hall | K13: Barbara Jean Hall
G14: Olive Loffler | I14: June Margery Hall | J14: Irene May McDougal | K14: Bryce Masters
I15: Simon Leigh Robertson | J15: Short | K15: Carol Edith Ryder
J16: Kyle Short | K16: Cecil Dudley Hall
A17: Robert King | B17: Ancestry | C17: 4th Cousin | D17: 2nd Cousin 1xremoved | E17: 69cM | F17: Frederick William Hall | G17: Charlotte Lydia Brinkley | H17: 1G Grandparents | I17: Maud Bessie Hall | J17: Violet Selina Hall | K17: Cecil Hall
I18: June Margery Hall | J18: Doreen Joan Ruffel | K18: Charles Henry Hall
I19: Simon Leigh Robertson | J19: Jane E Clayton | K19: Cherish Maxwell
J20: Robert King | K20: Clare Jane Daborn
A21: Sarah clennell | B21: MyHeritage | C21: 4th Cousin | D21: 5th Cousin | E21: 63.1cM | F21: Jasper Hall | G21: Mary Orders | H21: 4G Grandparents | I21: William Hall | J21: Frederick Hall | K21: Corinne Bachnsky
